Workbook

Sheet README
A1: Public statements on critical minerals: China, the US and Latin America
A2: Source file: statements.csv (provided by the user). No values were changed; only formatting, country names and readable labels were added.
A4: Sheets
A5: Statements | B5: Readable table, one row per statement, sorted by date. Filter with the header arrows. The Source column links to the original article or document.
A6: Coverage | B6: Count tables by country, speaker bloc, stance and mineral. All counts are formulas on the Data sheet.
A7: Data | B7: All 29 original fields from statements.csv, in the original row order, unchanged.
A9: Key facts
A10: Statements | B10: =COUNTA(Data!$A$2:$A$418)
A11: Date range | B11: =MIN(Data!$C$2:$C$418)&" to "&MAX(Data!$C$2:$C$418)
A12: In 12-country scope | B12: =COUNTA(Data!$A$2:$A$418)-COUNTIF(Data!$D$2:$D$418,"MEX")-COUNTIF(Data!$D$2:$D$418,"PAN")-COUNTIF(Data!$D$2:$D$418,"REG")
A13: Outside scope | B13: Mexico (MEX) and Panama (PAN) are outside the 12 South American states; REG marks region-wide statements. They are kept and flagged in the "In 12-country scope" column.
A15: Added labels
A16: Country | B16: ISO-3 codes from the "country" field mapped to names (REG = Regional).
A17: In 12-country scope | B17: Yes if the country is one of Argentina, Bolivia, Brazil, Chile, Colombia, Ecuador, Guyana, Paraguay, Peru, Suriname, Uruguay, Venezuela.
A18: Labels | B18: Underscores replaced with spaces and semicolons with commas in channel, minerals, themes, stance, source type and verification. Raw codes remain on the Data sheet.
A19: Verification | B19: Taken as given in the CSV: primary verified, secondary reported, or unverified.
A21: Regenerated from political_statements_minerals.csv by pipeline/scripts/statements_workbook.py on 2026-10-09: 417 records.

Sheet Statements
A1: ID | B1: Date | C1: Country | D1: In 12-country scope | E1: Speaker | F1: Role | G1: Speaker bloc | H1: Channel | I1: Event / context | J1: Summary | K1: Minerals | L1: Themes | M1: Stance on China | N1: Stance on US | O1: Quote (original) | P1: Quote (English) | Q1: Language | R1: Source | S1: Source type | T1: Verification | U1: Notes
A2: PS-0001 | B2: 2019-03 | C2: Peru | D2: Yes | E2: Paola Bustamante | F2: Minister of Development and Social Inclusion of Peru | G2: LatAm executive | H2: press conference | I2: Fuerabamba blockade of Las Bambas mining road; failed ministerial negotiation visit | J2: After protesters threw rocks at a government helicopter carrying a three-minister delegation to negotiate an end to a 51-day Fuerabamba community blockade of the Las Bambas copper mine road, Bustamante said the government would maintain its willingness to dialogue. | K2: copper | L2: labor social conflict, indigenous community rights | M2: not mentioned | N2: not mentioned | O2: We went with a disposition for dialogue and that's why we're going to continue with that disposition and see how things shape up tomorrow. | P2: We went with a disposition for dialogue and that's why we're going to continue with that disposition and see how things shape up tomorrow. | Q2: en | R2: Reuters via The Borneo Post (PressReader) | S2: news media | T2: secondary reported | U2: Exact day not given (Wednesday before 29 Mar 2019, likely 27 Mar); quote is English wire translation of Spanish original
A3: PS-0002 | B3: 2019-03-05 | C3: Brazil | D3: Yes | E3: Bento Albuquerque | F3: Minister of Mines and Energy of Brazil | G3: LatAm executive | H3: speech | I3: Meeting with mining investors in Canada (PDAC, Toronto) | J3: Albuquerque told investors in Canada that the government was studying authorising mining in indigenous lands and border areas, arguing restrictions fostered illegal activity, and favoured opening uranium research to private investment. | K3: mining general | L3: indigenous community rights, foreign investment, sovereignty | M3: not mentioned | N3: not mentioned | O3: As restrições aplicadas a essas áreas não têm favorecido seu desenvolvimento. | P3: The restrictions applied to these areas have not favoured their development. | Q3: pt | R3: Congresso em Foco | S3: news media | T3: secondary reported | U3: Event name PDAC inferred from date/location
A4: PS-0003 | B4: 2019-07-16 | C4: Peru | D4: Yes | E4: Elmer Cáceres Llica | F4: Regional Governor of Arequipa | G4: LatAm executive | H4: press conference | I4: Tía María license protests, Tambo Valley | J4: The Arequipa governor, backed by over 50 civil organizations, gave the central government 72 hours to declare the Tía María construction license null, while pursuing legal remedies and peaceful protests. | K4: copper | L4: environment water, labor social conflict | M4: not mentioned | N4: not mentioned | O4: Le daremos al Gobierno central 72 horas para que resuelva el tema de la licencia de construcción, o sea que declare su nulidad de oficio | P4: We will give the central government 72 hours to resolve the construction license issue, that is, to declare it null ex officio | Q4: es | R4: La República | S4: news media | T4: secondary reported
A5: PS-0004 | B5: 2019-07-16 | C5: Peru | D5: Yes | E5: Martín Vizcarra | F5: President of Peru | G5: LatAm executive | H5: press conference | I5: Protests over Tía María construction license granted to Southern Peru (9 Jul 2019) | J5: Vizcarra said the construction license granted to Southern Peru for Tía María could not be annulled because the company had completed the administrative process, but called for dialogue and said construction would need proper conditions. | K5: copper | L5: labor social conflict, environment water, foreign investment | M5: not mentioned | N5: not mentioned | O5: No se puede anular, tenemos que conversar y fruto del diálogo, encontremos las soluciones y consensos | P5: It cannot be annulled; we have to talk, and through dialogue find solutions and consensus | Q5: es | R5: El Búho | S5: news media | T5: secondary reported
A6: PS-0005 | B6: 2019-09-06 | C6: Chile | D6: Yes | E6: Pablo Terrazas | F6: Executive Vice President of CORFO | G6: LatAm executive | H6: legislative debate | I6: Chamber of Deputies Economy Commission session on lithium and Tianqi-SQM | J6: CORFO head briefed deputies on lithium contracts, Tianqi's stake in SQM and the planned Chilean Institute of Clean Technologies in Antofagasta, funded with SQM contributions, for lithium R&D. | K6: lithium | L6: technology transfer, value added industrialization, foreign investment | M6: neutral | N6: not mentioned | O6: De aquí a fin de año, ya vamos a tener a algún consorcio liderando la creación de este instituto | P6: By the end of the year we will have a consortium leading the creation of this institute | Q6: es | R6: Cámara de Diputadas y Diputados | S6: legislative record | T6: primary verified | U6: Quote truncated to stay within 30 words; institute to have >US$200m for R&D
A7: PS-0006 | B7: 2019-09-06 | C7: Chile | D7: Yes | E7: Renato Garín | F7: Deputy, Chair-level member of Economy Commission | G7: LatAm legislature | H7: legislative debate | I7: Chamber of Deputies Economy Commission session on lithium and Tianqi-SQM | J7: Deputy Garín voiced concern about Chinese state influence over SQM through Tianqi and said Chile must retain sovereignty over its lithium resources and technology development. | K7: lithium | L7: sovereignty, geopolitics security, technology transfer | M7: negative | N7: not mentioned | Q7: es | R7: Cámara de Diputadas y Diputados | S7: legislative record | T7: primary verified | U7: Paraphrase from Chamber press note; no verbatim quote
A8: PS-0007 | B8: 2019-10-13 | C8: Peru | D8: Yes | E8: Raúl Molina Martínez | F8: Deputy Minister of Territorial Governance (PCM) | G8: LatAm executive | H8: official statement | I8: Chumbivilcas blockade of southern mining corridor used by Las Bambas | J8: The PCM vice minister urged Chumbivilcas communities to lift their blockade of the road used by Las Bambas to haul copper concentrate, stressing it is a public road and that demands must be legally viable. | K8: copper | L8: labor social conflict, infrastructure ports | M8: not mentioned | N8: not mentioned | O8: It is not possible to prevent the free movement of vehicles through the runway, including the miner's trucks, because it is a public road. | P8: It is not possible to prevent the free movement of vehicles through the runway, including the miner's trucks, because it is a public road. | Q8: en | R8: Reuters via MINING.COM | S8: news media | T8: secondary reported | U8: Quote is English wire translation; date is article date
A9: PS-0008 | B9: 2019-10-28 | C9: Peru | D9: Yes | E9: Juan Carlos Liu | F9: Minister of Energy and Mines of Peru | G9: LatAm executive | H9: press conference | I9: Mining Council review of Tía María license | J9: Liu said the Tía María license case was for the autonomous Mining Council to decide and that the government, following presidential guidelines, would abide by its ruling while promoting dialogue in the Tambo Valley. | K9: copper | L9: corruption governance, labor social conflict | M9: not mentioned | N9: not mentioned | O9: El caso de Tía María es un caso que está para la decisión de la Comisión de Minería. | P9: The Tía María case is one awaiting the decision of the Mining Commission. | Q9: es | R9: ProActivo | S9: news media | T9: secondary reported
A10: PS-0009 | B10: 2020-04 | C10: Bolivia | D10: Yes | E10: José Luis Parada | F10: Minister of Economy and Public Finance (Áñez interim government) | G10: LatAm executive | H10: interview | I10: Interim government economic policy, COVID-19 period | J10: Interim-government economy minister Parada said two or three companies from different countries would invest in lithium from the Uyuni salt flat and that policies to attract foreign partners were being prepared. | K10: lithium | L10: foreign investment | M10: not mentioned | N10: not mentioned | Q10: es | R10: Tiempo Argentino | S10: news media | T10: secondary reported | U10: Paraphrase from secondary source (left-leaning outlet); exact day in late April 2020 unknown; no verbatim quote seen.
A11: PS-0010 | B11: 2020-07-25 | C11: Bolivia | D11: Yes | E11: Evo Morales | F11: Former President of Bolivia (in exile) | G11: Other (business, civil society, third countries) | H11: social media post | I11: Twitter exchange with Elon Musk | J11: Responding to Elon Musk's 'We will coup whoever we want' tweet, Morales said it was further proof that the 2019 coup was over Bolivian lithium and vowed to defend Bolivia's resources. | K11: lithium | L11: sovereignty, geopolitics security | M11: not mentioned | N11: negative | O11: Otra prueba más de que el golpe fue por el litio boliviano; y dos masacres como saldo. ¡Defenderemos siempre nuestros recursos! | P11: Yet more proof that the coup was over Bolivian lithium; with two massacres as the toll. We will always defend our resources! | Q11: es | R11: La República (Peru) | S11: news media | T11: secondary reported | U11: Tweet quoted by media; stance_us coded for US corporate actor (Musk/Tesla).
A12: PS-0011 | B12: 2020-09-28 | C12: Brazil | D12: Yes | E12: Jair Bolsonaro | F12: President of Brazil | G12: LatAm executive | H12: speech | I12: Launch of the Mining and Development Program (PMD), Palácio do Planalto | J12: At the launch of the government's Mining and Development Program, Bolsonaro received a niobium coin from Minister Bento Albuquerque and praised niobium combined with graphene as able to revolutionise the car industry; the program included advancing a bill on mining in indigenous lands. | K12: niobium, mining general | L12: value added industrialization, technology transfer, indigenous community rights | M12: not mentioned | N12: not mentioned | O12: juntamente com o grafeno é capaz de produzir maravilhas | P12: together with graphene it is capable of producing wonders | Q12: pt | R12: Poder360 | S12: news media | T12: secondary reported | U12: Bolsonaro left PSL in Nov 2019
A13: PS-0012 | B13: 2020-11-10 | C13: Bolivia | D13: Yes | E13: Evo Morales | F13: Former President of Bolivia; MAS leader | G13: Other (business, civil society, third countries) | H13: press conference | I13: Return to Bolivia from exile, Uyuni/Potosí tour | J13: On his return to Bolivia, Morales said lithium reserves were the motive for the 2019 'coup', that industrialized countries want Latin America only for raw materials, and that his lithium industrialization plan would resume under President Arce. | K13: lithium | L13: value added industrialization, sovereignty, geopolitics security | M13: not mentioned | N13: not mentioned | O13: allí donde los pueblos son dueños de los recursos naturales, preparan bases e intervenciones militares e incluso golpes de Estado | P13: wherever peoples own their natural resources, they prepare bases and military interventions and even coups d'état | Q13: es | R13: Público | S13: news media | T13: secondary reported | U13: Also reported by Gestión (https://gestion.pe/mundo/internacional/evo-morales-anuncia-que-se-reactivara-su-plan-de-litio-apenas-llegado-a-bolivia-noticia/): 'El plan que teníamos lo vamos a retomar ahora con el Lucho presidente'.
A14: PS-0013 | B14: 2020-12-04 | C14: Peru | D14: Yes | E14: Francisco Sagasti | F14: President of Peru (transitional) | G14: LatAm executive | H14: press conference | I14: Press conference with foreign media accredited in Peru | J14: Sagasti said his transitional government had no mandate to change economic direction and would ensure that foreign investments already under way, including in mining, continue, while arguing Peru should diversify beyond being a mining country. | K14: mining general | L14: foreign investment | M14: not mentioned | N14: not mentioned | O14: hará lo que hay que hacer para que continúen las inversiones extranjeras ya en proceso, ya sea en la minería o en otros sectores | P14: will do what must be done so that foreign investments already under way continue, whether in mining or other sectors | Q14: es | R14: ProActivo | S14: news media | T14: secondary reported | U14: Quote is in reported (third-person) form as published
A15: PS-0014 | B15: 2021-04-16 | C15: Peru | D15: Yes | E15: Ana María Córdova | F15: Legal representative of Perú Libre (Pedro Castillo campaign) | G15: LatAm party/candidate | H15: campaign statement | I15: 2021 presidential runoff campaign | J15: Speaking for candidate Pedro Castillo, Córdova said the party would not expropriate or nationalize mines but would renegotiate contract conditions so the state and local populations get a bigger share of profits. | K15: mining general, copper | L15: royalties taxation, state control nationalization, foreign investment | M15: not mentioned | N15: not mentioned | O15: Not to expropriate them, not to nationalize or anything, but so that the conditions in some way also favor populations where these industries or mining operations are involved | P15: Not to expropriate them, not to nationalize or anything, but so that the conditions in some way also favor populations where these industries or mining operations are involved | Q15: en | R15: Bloomberg via Mining Weekly | S15: news media | T15: secondary reported | U15: English translation published by Bloomberg; original Spanish wording not seen
A16: PS-0015 | B16: 2021-06-15 | C16: Argentina | D16: Yes | E16: Martín de los Ríos | F16: Minister of Production of Salta (for Gov. Gustavo Sáenz) | G16: LatAm executive | H16: interview | I16: Reaction to national lithium nationalization proposals | J16: Salta's production minister said the three lithium provinces formed the Mesa del Litio on the basis that lithium is a provincial resource and that nationalization initiatives create instability for investors. | K16: lithium | L16: state control nationalization, sovereignty, foreign investment | M16: not mentioned | N16: not mentioned | Q16: es | R16: Ámbito | S16: news media | T16: secondary reported | U16: Only translated rendering seen; quote left blank.
A17: PS-0016 | B17: 2021-06-15 | C17: Argentina | D17: Yes | E17: Miguel Soler | F17: Secretary of Mining of Jujuy (Morales government) | G17: LatAm executive | H17: interview | I17: Reaction to national lithium nationalization proposals | J17: Jujuy's mining secretary said proposals to nationalize lithium are unconstitutional because they interfere with provincial ownership of resources, and that Jujuy should make its own decisions. | K17: lithium | L17: state control nationalization, sovereignty | M17: not mentioned | N17: not mentioned | Q17: es | R17: Ámbito | S17: news media | T17: secondary reported | U17: Only translated rendering seen; quote left blank.
A18: PS-0017 | B18: 2021-09-23 | C18: Peru | D18: Yes | E18: Pedro Francke | F18: Minister of Economy and Finance of Peru | G18: LatAm executive | H18: interview | I18: Proposed tax reform targeting mining windfall profits | J18: Francke argued that with copper above US$4/lb and costs around US$1/lb, the state should capture extraordinary mining profits and redistribute mining wealth through tax reform. | K18: copper, mining general | L18: royalties taxation | M18: not mentioned | N18: not mentioned | O18: Hay que redistribuir la riqueza, en particular la riqueza minera | P18: We must redistribute wealth, particularly mining wealth | Q18: es | R18: La República | S18: news media | T18: secondary reported
A19: PS-0018 | B19: 2021-10-01 | C19: Peru | D19: Yes | E19: Iván Merino | F19: Minister of Energy and Mines of Peru | G19: LatAm executive | H19: interview | I19: Three-week blockade of Las Bambas road in Chumbivilcas | J19: Merino partly blamed MMG's short-term decision to haul Las Bambas copper concentrate on a dirt road for unrest with communities, and proposed a train line as a longer-term solution. | K19: copper | L19: labor social conflict, infrastructure ports | M19: not mentioned | N19: not mentioned | O19: They made short-term decisions and that has a cost | P19: They made short-term decisions and that has a cost | Q19: en | R19: Reuters via Mining Weekly | S19: news media | T19: secondary reported | U19: English wire translation
A20: PS-0019 | B20: 2021-11 | C20: Peru | D20: Yes | E20: Mirtha Vásquez | F20: President of the Council of Ministers of Peru | G20: LatAm executive | H20: official statement | I20: Agreement with Ayacucho communities on mine closures | J20: Vásquez signed an agreement with Ayacucho communities confirming the closure of four mining operations and said mining expansions in the province would not be approved, prompting business backlash; a vice minister later said expansion plans could still be submitted. | K20: mining general, silver | L20: environment water, indigenous community rights, labor social conflict | M20: not mentioned | N20: not mentioned | Q20: es | R20: Bloomberg Línea | S20: news media | T20: secondary reported | U20: Agreement dated c. 19-20 Nov 2021; silver tag because affected mines (Hochschild) are gold-silver operations
A21: PS-0020 | B21: 2021-11-20 | C21: Argentina | D21: Yes | E21: Gustavo Sáenz; Gerardo Morales; Raúl Jalil | F21: Governors of Salta, Jujuy and Catamarca | G21: LatAm executive | H21: joint declaration or mou | I21: Creation of the Región Minera del Litio | J21: The three governors signed a treaty forming the Lithium Mining Region to coordinate infrastructure, production, technical and environmental matters across lithium research, extraction, industrialization and trade. | K21: lithium | L21: value added industrialization, infrastructure ports, environment water | M21: not mentioned | N21: not mentioned | O21: determinar las bases para generar condiciones de reciprocidad y coordinar esfuerzos en materia de infraestructura, producción, cuestiones técnicas ambientales | P21: lay the foundations to create reciprocal conditions and coordinate efforts on infrastructure, production, technical and environmental issues | Q21: es | R21: Más Energía (LM Neuquén) | S21: news media | T21: secondary reported | U21: Quote by Sáenz; Mesa del Litio precedent.
A22: PS-0021 | B22: 2021-11-22 | C22: Peru | D22: Yes | E22: Pedro Castillo | F22: President of Peru | G22: LatAm executive | H22: official statement | I22: Controversy over PM Vásquez's announced closure of four mines in Ayacucho | J22: Amid market turmoil after the premier agreed with Ayacucho communities to close four mining operations, Castillo said there would be no unilateral or arbitrary decisions and reaffirmed his commitment to guarantee private investment including mining. | K22: mining general | L22: foreign investment, environment water, indigenous community rights | M22: not mentioned | N22: not mentioned | O22: No ha existido ni existirán decisiones unilaterales ni arbitrarias | P22: There have not been, nor will there be, unilateral or arbitrary decisions | Q22: es | R22: Bloomberg Línea | S22: news media | T22: secondary reported
A23: PS-0022 | B23: 2021-12-16 | C23: Peru | D23: Yes | E23: Mirtha Vásquez | F23: President of the Council of Ministers of Peru | G23: LatAm executive | H23: press conference | I23: Chumbivilcas blockade halting Las Bambas | J23: With the Las Bambas road blockade past 20 days, Vásquez said the government was evaluating options including eviction of protesters and, as a last resort, a state of emergency in Chumbivilcas. | K23: copper | L23: labor social conflict, corruption governance | M23: not mentioned | N23: not mentioned | O23: Hay varias opciones que evaluar. No podemos permitir que se estén vulnerando ciertos derechos | P23: There are several options to evaluate. We cannot allow certain rights to be violated | Q23: es | R23: ProActivo | S23: news media | T23: secondary reported
A24: PS-0023 | B24: 2021-12-21 | C24: Peru | D24: Yes | E24: Baltazar Lantarón | F24: Regional Governor of Apurímac | G24: LatAm executive | H24: official statement | I24: Las Bambas shutdown due to corridor blockade | J24: Lantarón criticized the Executive's negotiators as pusillanimous over the Las Bambas corridor blockade, warned of lost royalties and mining canon for Apurímac, and requested a 120-day emergency declaration on the southern mining corridor. | K24: copper | L24: royalties taxation, labor social conflict | M24: not mentioned | N24: not mentioned | O24: la actitud pusilánime de los negociadores del Ejecutivo están generado nefastas consecuencias económicas | P24: the pusillanimous attitude of the Executive's negotiators is generating disastrous economic consequences | Q24: es | R24: ProActivo | S24: news media | T24: secondary reported
A25: PS-0024 | B25: 2022-01 | C25: Chile | D25: Yes | E25: Juan Carlos Jobet | F25: Minister of Mining and Energy | G25: LatAm executive | H25: interview | I25: Defence of lithium tender against incoming government's request to postpone | J25: Jobet argued Chile had failed to raise lithium output while other countries advanced, and said the tender (about 4% of reserves) did not mortgage the next government's agenda. | K25: lithium | L25: foreign investment, state control nationalization | M25: not mentioned | N25: not mentioned | O25: hemos sido incapaces de aumentar la producción y, mientras hacemos eso, los otros países avanzan | P25: we have been unable to increase production and, while we do that, other countries advance | Q25: es | R25: CNN Chile | S25: news media | T25: secondary reported | U25: Exact day not given; January 2022
A26: PS-0025 | B26: 2022-01-06 | C26: Chile | D26: Yes | E26: Ricardo Díaz | F26: Governor of Antofagasta Region | G26: LatAm executive | H26: official statement | I26: Complaint to Comptroller over lithium tender | J26: Antofagasta governor said his government filed a complaint with the Comptroller over the Piñera administration's lithium tender, arguing regional and indigenous Atacameño voices were not consulted. | K26: lithium | L26: indigenous community rights, sovereignty, corruption governance | M26: not mentioned | N26: not mentioned | O26: No se puede hacer un proceso de consulta, en donde se hipoteca el futuro de nuestra región, sin considerar la voz de los que habitamos este territorio. | P26: You cannot carry out a consultation process that mortgages the future of our region without considering the voice of those of us who live in this territory. | Q26: es | R26: T13 | S26: news media | T26: secondary reported
A27: PS-0026 | B27: 2022-01-07 | C27: Chile | D27: Yes | E27: Sebastián Piñera | F27: President of Chile | G27: LatAm executive | H27: press conference | I27: Visit to O'Higgins Region; defence of lithium tender | J27: Piñera defended the international lithium tender for about 4.4% of known reserves as transparent and Comptroller-approved, noting Chile had lost lithium leadership to Australia and saying a national lithium company, as proposed by Boric, could be done. | K27: lithium | L27: foreign investment, state control nationalization, corruption governance | M27: not mentioned | N27: not mentioned | O27: El litio es hoy día un mineral esencial para la sociedad que viene | P27: Lithium is today an essential mineral for the society to come | Q27: es | R27: El Dínamo | S27: news media | T27: secondary reported
A28: PS-0027 | B28: 2022-01-10 | C28: Chile | D28: Yes | E28: Rodrigo Cerda | F28: Minister of Finance | G28: LatAm executive | H28: interview | I28: Canal 13 interview on lithium tender | J28: Finance minister said the lithium tender was not a lock-in ("amarre"), that lithium would remain Chilean and taxed, and that the government was listening to the president-elect's request to postpone it. | K28: lithium | L28: royalties taxation, state control nationalization | M28: not mentioned | N28: not mentioned | O28: El litio va a seguir siendo de los chilenos | P28: Lithium will continue to belong to Chileans | Q28: es | R28: CNN Chile | S28: news media | T28: secondary reported
A29: PS-0028 | B29: 2022-01-12 | C29: Chile | D29: Yes | E29: Esteban Velásquez | F29: Deputy; President of Chamber Mining Commission | G29: LatAm legislature | H29: legislative debate | I29: Chamber Mining Commission session on lithium tender | J29: Mining Commission chair criticised the Piñera government for ignoring calls to halt the lithium tender; opposition deputies announced judicial and administrative actions to annul it. | K29: lithium | L29: corruption governance, state control nationalization | M29: not mentioned | N29: not mentioned | O29: El Gobierno del Presidente Piñera no escuchó ningún llamado | P29: President Piñera's government did not listen to any call | Q29: es | R29: El Mostrador | S29: news media | T29: secondary reported
A30: PS-0029 | B30: 2022-01-12 | C30: Chile | D30: Yes | E30: Gabriel Boric | F30: President-elect of Chile | G30: LatAm party/candidate | H30: press conference | I30: Reaction to award of lithium tender to BYD and Servicios y Operaciones Mineras del Norte | J30: President-elect Boric called the outgoing government's lithium tender award bad news reminiscent of the "leyes de amarre" and said his team would review its details. | K30: lithium | L30: state control nationalization, corruption governance | M30: not mentioned | N30: not mentioned | O30: es una mala noticia y me recuerda a esas leyes de amarre | P30: it is bad news and reminds me of those lock-in laws | Q30: es | R30: El Mostrador | S30: news media | T30: secondary reported | U30: speaker_type coded as candidate because president-elect, not yet in office
A31: PS-0030 | B31: 2022-02-02 | C31: Mexico | D31: No | E31: Andrés Manuel López Obrador | F31: President of Mexico | G31: LatAm executive | H31: press conference | I31: Mañanera; announcement of state lithium company | J31: AMLO said existing mining concessions did not cover lithium, which he called a strategic mineral belonging to the nation, and that the state would exploit it; he said Mexico did not want to be a territory of conflict between Russia, China or the US. | K31: lithium | L31: state control nationalization, sovereignty, geopolitics security, foreign investment | M31: neutral | N31: neutral | O31: el litio lo va a explotar la nación. El litio ya, para que se entienda bien, no es ni siquiera del Gobierno o del Estado, el litio es del pueblo | P31: lithium will be exploited by the nation. Lithium, to be clear, does not even belong to the government or the state, lithium belongs to the people | Q31: es | R31: Emol (EFE) | S31: news media | T31: secondary reported
A32: PS-0031 | B32: 2022-02-06 | C32: Argentina | D32: Yes | E32: Xi Jinping; Alberto Fernández | F32: President of China; President of Argentina | G32: China | H32: joint declaration or mou | I32: Fernández state visit to Beijing; Argentina joins Belt and Road | J32: Chinese readout of the Xi-Fernández meeting says the sides will deepen cooperation in trade, agriculture, energy, mining, infrastructure, investment and finance, with China helping expand Argentina's exports. | K32: mining general | L32: diplomatic relations, foreign investment, infrastructure ports | M32: positive | N32: not mentioned | O32: la cooperación en áreas de comercio, agricultura, energía, minería, infraestructura, inversión, financiación y lucha antiepidémica | P32: cooperation in the areas of trade, agriculture, energy, mining, infrastructure, investment, financing and the fight against the epidemic | Q32: es | R32: Ministry of Foreign Affairs of the PRC (Spanish) | S32: primary official | T32: primary verified | U32: Mining only listed among sectors.
A33: PS-0032 | B33: 2022-03-31 | C33: Regional | D33: No | E33: Marco Rubio | F33: U.S. Senator (R-FL), Ranking Member, SFRC Subcommittee on the Western Hemisphere | G33: United States | H33: legislative debate | I33: SFRC Western Hemisphere subcommittee hearing 'China's Role in Latin America and the Caribbean' | J33: Rubio said the Chinese Communist Party pushes Latin American countries to stay dependent on mining and natural-resource exports rather than helping them develop and industrialize. | K33: mining general | L33: geopolitics security, value added industrialization | M33: negative | N33: positive | O33: the Chinese Communist Party is pushing countries to remain dependent on mining and other—and the export of other natural resources | P33: the Chinese Communist Party is pushing countries to remain dependent on mining and other—and the export of other natural resources | Q33: en | R33: U.S. Senate Foreign Relations Committee (hearing transcript) | S33: legislative record | T33: primary verified | U33: Ranking-member role inferred, not confirmed on page.
A34: PS-0033 | B34: 2022-03-31 | C34: Regional | D34: No | E34: Tim Kaine | F34: U.S. Senator (D-VA), Chair, SFRC Subcommittee on the Western Hemisphere | G34: United States | H34: legislative debate | I34: SFRC Western Hemisphere subcommittee hearing 'China's Role in Latin America and the Caribbean' | J34: In his opening statement Kaine said China continues its quest for natural resources and raw materials across Latin America, citing lithium in Argentina, Bolivia and Chile and copper in Peru. | K34: lithium, copper | L34: geopolitics security, foreign investment | M34: negative | N34: positive | O34: China continues its quest for natural resources and raw materials throughout the region, including lithium in places like Argentina, Bolivia, and Chile or copper in Peru. | P34: China continues its quest for natural resources and raw materials throughout the region, including lithium in places like Argentina, Bolivia, and Chile or copper in Peru. | Q34: en | R34: U.S. Senate Foreign Relations Committee (hearing transcript) | S34: legislative record | T34: primary verified | U34: Subcommittee chair role inferred (Kaine chaired the WH subcommittee in the 117th Congress).
A35: PS-0034 | B35: 2022-04-18 | C35: Mexico | D35: No | E35: Andrés Manuel López Obrador | F35: President of Mexico | G35: LatAm executive | H35: press conference | I35: Mañanera after failure of constitutional electricity reform; call to pass Mining Law reform | J35: AMLO urged legislators to approve his Mining Law reform nationalizing lithium, saying it should be used only for national development and that a state company would explore, extract, process and sell it. | K35: lithium | L35: state control nationalization, sovereignty, geopolitics security | M35: not mentioned | N35: not mentioned | O35: nacionalicemos el litio. Así de claro, que solo se utilice para el beneficio del desarrollo nacional. | P35: let's nationalize lithium. That clear, so that it is only used for the benefit of national development. | Q35: es | R35: El Financiero | S35: news media | T35: secondary reported
A36: PS-0035 | B36: 2022-04-18 | C36: Mexico | D36: No | E36: Cámara de Diputados de México | F36: Chamber of Deputies | G36: LatAm legislature | H36: bill or law | I36: Vote on Mining Law reform declaring lithium of public utility | J36: The Chamber of Deputies approved in general the reform to the Mining Law nationalizing lithium by 298 votes in favour and 197 abstentions; PAN and PRI deputies abstained, while Movimiento Ciudadano voted against parts of it. | K36: lithium | L36: state control nationalization, sovereignty | M36: not mentioned | N36: not mentioned | Q36: es | R36: Expansión Política | S36: news media | T36: secondary reported | U36: In particular: 275 for, 187 abstentions, 24 against (MC).
A37: PS-0036 | B37: 2022-04-18 | C37: Mexico | D37: No | E37: Salomón Chertorivski | F37: Federal Deputy (Movimiento Ciudadano) | G37: LatAm legislature | H37: legislative debate | I37: Chamber of Deputies debate on lithium Mining Law reform | J37: Chertorivski argued that lithium concessions could not be prohibited by ordinary statute and that it had to be done through the Constitution. | K37: lithium | L37: state control nationalization, corruption governance | M37: not mentioned | N37: not mentioned | O37: No se puede prohibir en una ley una concesión, se tiene que hacer desde la Constitución | P37: A concession cannot be prohibited in a law, it has to be done from the Constitution | Q37: es | R37: Expansión Política | S37: news media | T37: secondary reported
A38: PS-0037 | B38: 2022-04-19 | C38: Mexico | D38: No | E38: Alejandro Armenta | F38: Senator (Morena) | G38: LatAm legislature | H38: legislative debate | I38: Senate debate on lithium Mining Law reform | J38: Morena senator Armenta defended the reform, arguing that the private sector would still participate since the state company would sell lithium to private firms. | K38: lithium | L38: state control nationalization, foreign investment | M38: not mentioned | N38: not mentioned | O38: Se lo vende a los particulares | P38: It is sold to private parties | Q38: es | R38: Expansión Política | S38: news media | T38: secondary reported
A39: PS-0038 | B39: 2022-04-19 | C39: Mexico | D39: No | E39: Damián Zepeda | F39: Senator (PAN) | G39: LatAm legislature | H39: legislative debate | I39: Senate debate on lithium Mining Law reform | J39: PAN senator Damián Zepeda opposed the lithium reform, arguing the government should not act as a businessman in lithium exploitation. | K39: lithium | L39: state control nationalization, foreign investment | M39: not mentioned | N39: not mentioned | O39: el gobierno es pésimo para ser empresario | P39: the government is terrible at being a businessman | Q39: es | R39: Expansión Política | S39: news media | T39: secondary reported
A40: PS-0039 | B40: 2022-04-19 | C40: Mexico | D40: No | E40: José Erandi Bermúdez | F40: Senator (PAN) | G40: LatAm legislature | H40: legislative debate | I40: Senate debate on lithium Mining Law reform | J40: Bermúdez criticized the reform for lacking precision on which minerals would be considered 'strategic'. | K40: lithium, critical minerals general | L40: state control nationalization, corruption governance | M40: not mentioned | N40: not mentioned | Q40: es | R40: Expansión Política | S40: news media | T40: secondary reported
...

Sheet Coverage
A1: Coverage of the statements dataset
A2: All counts are COUNTIFS/SUMPRODUCT formulas on the Data sheet; they update if rows are added inside the Data range.
A6: Statements by country (the "country" field) and speaker bloc
A7: Code | B7: Country | C7: LatAm executive | D7: United States | E7: LatAm legislature | F7: China | G7: Other (business, civil society, third countries) | H7: LatAm party/candidate | I7: LatAm state company | J7: LatAm judiciary | K7: Total
A8: CHL | B8: Chile | C8: =COUNTIFS(Data!$D$2:$D$418,$A8,Data!$H$2:$H$418,"LatAm executive") | D8: =COUNTIFS(Data!$D$2:$D$418,$A8,Data!$H$2:$H$418,"United States") | E8: =COUNTIFS(Data!$D$2:$D$418,$A8,Data!$H$2:$H$418,"LatAm legislature") | F8: =COUNTIFS(Data!$D$2:$D$418,$A8,Data!$H$2:$H$418,"China") | G8: =COUNTIFS(Data!$D$2:$D$418,$A8,Data!$H$2:$H$418,"Other (business, civil society, third countries)") | H8: =COUNTIFS(Data!$D$2:$D$418,$A8,Data!$H$2:$H$418,"LatAm party/candidate") | I8: =COUNTIFS(Data!$D$2:$D$418,$A8,Data!$H$2:$H$418,"LatAm state company") | J8: =COUNTIFS(Data!$D$2:$D$418,$A8,Data!$H$2:$H$418,"LatAm judiciary") | K8: =SUM(C6:J6)
A9: PER | B9: Peru | C9: =COUNTIFS(Data!$D$2:$D$418,$A9,Data!$H$2:$H$418,"LatAm executive") | D9: =COUNTIFS(Data!$D$2:$D$418,$A9,Data!$H$2:$H$418,"United States") | E9: =COUNTIFS(Data!$D$2:$D$418,$A9,Data!$H$2:$H$418,"LatAm legislature") | F9: =COUNTIFS(Data!$D$2:$D$418,$A9,Data!$H$2:$H$418,"China") | G9: =COUNTIFS(Data!$D$2:$D$418,$A9,Data!$H$2:$H$418,"Other (business, civil society, third countries)") | H9: =COUNTIFS(Data!$D$2:$D$418,$A9,Data!$H$2:$H$418,"LatAm party/candidate") | I9: =COUNTIFS(Data!$D$2:$D$418,$A9,Data!$H$2:$H$418,"LatAm state company") | J9: =COUNTIFS(Data!$D$2:$D$418,$A9,Data!$H$2:$H$418,"LatAm judiciary") | K9: =SUM(C6:J6)
A10: BRA | B10: Brazil | C10: =COUNTIFS(Data!$D$2:$D$418,$A10,Data!$H$2:$H$418,"LatAm executive") | D10: =COUNTIFS(Data!$D$2:$D$418,$A10,Data!$H$2:$H$418,"United States") | E10: =COUNTIFS(Data!$D$2:$D$418,$A10,Data!$H$2:$H$418,"LatAm legislature") | F10: =COUNTIFS(Data!$D$2:$D$418,$A10,Data!$H$2:$H$418,"China") | G10: =COUNTIFS(Data!$D$2:$D$418,$A10,Data!$H$2:$H$418,"Other (business, civil society, third countries)") | H10: =COUNTIFS(Data!$D$2:$D$418,$A10,Data!$H$2:$H$418,"LatAm party/candidate") | I10: =COUNTIFS(Data!$D$2:$D$418,$A10,Data!$H$2:$H$418,"LatAm state company") | J10: =COUNTIFS(Data!$D$2:$D$418,$A10,Data!$H$2:$H$418,"LatAm judiciary") | K10: =SUM(C6:J6)
A11: ARG | B11: Argentina | C11: =COUNTIFS(Data!$D$2:$D$418,$A11,Data!$H$2:$H$418,"LatAm executive") | D11: =COUNTIFS(Data!$D$2:$D$418,$A11,Data!$H$2:$H$418,"United States") | E11: =COUNTIFS(Data!$D$2:$D$418,$A11,Data!$H$2:$H$418,"LatAm legislature") | F11: =COUNTIFS(Data!$D$2:$D$418,$A11,Data!$H$2:$H$418,"China") | G11: =COUNTIFS(Data!$D$2:$D$418,$A11,Data!$H$2:$H$418,"Other (business, civil society, third countries)") | H11: =COUNTIFS(Data!$D$2:$D$418,$A11,Data!$H$2:$H$418,"LatAm party/candidate") | I11: =COUNTIFS(Data!$D$2:$D$418,$A11,Data!$H$2:$H$418,"LatAm state company") | J11: =COUNTIFS(Data!$D$2:$D$418,$A11,Data!$H$2:$H$418,"LatAm judiciary") | K11: =SUM(C6:J6)
A12: BOL | B12: Bolivia | C12: =COUNTIFS(Data!$D$2:$D$418,$A12,Data!$H$2:$H$418,"LatAm executive") | D12: =COUNTIFS(Data!$D$2:$D$418,$A12,Data!$H$2:$H$418,"United States") | E12: =COUNTIFS(Data!$D$2:$D$418,$A12,Data!$H$2:$H$418,"LatAm legislature") | F12: =COUNTIFS(Data!$D$2:$D$418,$A12,Data!$H$2:$H$418,"China") | G12: =COUNTIFS(Data!$D$2:$D$418,$A12,Data!$H$2:$H$418,"Other (business, civil society, third countries)") | H12: =COUNTIFS(Data!$D$2:$D$418,$A12,Data!$H$2:$H$418,"LatAm party/candidate") | I12: =COUNTIFS(Data!$D$2:$D$418,$A12,Data!$H$2:$H$418,"LatAm state company") | J12: =COUNTIFS(Data!$D$2:$D$418,$A12,Data!$H$2:$H$418,"LatAm judiciary") | K12: =SUM(C6:J6)
A13: MEX | B13: Mexico | C13: =COUNTIFS(Data!$D$2:$D$418,$A13,Data!$H$2:$H$418,"LatAm executive") | D13: =COUNTIFS(Data!$D$2:$D$418,$A13,Data!$H$2:$H$418,"United States") | E13: =COUNTIFS(Data!$D$2:$D$418,$A13,Data!$H$2:$H$418,"LatAm legislature") | F13: =COUNTIFS(Data!$D$2:$D$418,$A13,Data!$H$2:$H$418,"China") | G13: =COUNTIFS(Data!$D$2:$D$418,$A13,Data!$H$2:$H$418,"Other (business, civil society, third countries)") | H13: =COUNTIFS(Data!$D$2:$D$418,$A13,Data!$H$2:$H$418,"LatAm party/candidate") | I13: =COUNTIFS(Data!$D$2:$D$418,$A13,Data!$H$2:$H$418,"LatAm state company") | J13: =COUNTIFS(Data!$D$2:$D$418,$A13,Data!$H$2:$H$418,"LatAm judiciary") | K13: =SUM(C6:J6)
A14: REG | B14: Regional | C14: =COUNTIFS(Data!$D$2:$D$418,$A14,Data!$H$2:$H$418,"LatAm executive") | D14: =COUNTIFS(Data!$D$2:$D$418,$A14,Data!$H$2:$H$418,"United States") | E14: =COUNTIFS(Data!$D$2:$D$418,$A14,Data!$H$2:$H$418,"LatAm legislature") | F14: =COUNTIFS(Data!$D$2:$D$418,$A14,Data!$H$2:$H$418,"China") | G14: =COUNTIFS(Data!$D$2:$D$418,$A14,Data!$H$2:$H$418,"Other (business, civil society, third countries)") | H14: =COUNTIFS(Data!$D$2:$D$418,$A14,Data!$H$2:$H$418,"LatAm party/candidate") | I14: =COUNTIFS(Data!$D$2:$D$418,$A14,Data!$H$2:$H$418,"LatAm state company") | J14: =COUNTIFS(Data!$D$2:$D$418,$A14,Data!$H$2:$H$418,"LatAm judiciary") | K14: =SUM(C6:J6)
A15: ECU | B15: Ecuador | C15: =COUNTIFS(Data!$D$2:$D$418,$A15,Data!$H$2:$H$418,"LatAm executive") | D15: =COUNTIFS(Data!$D$2:$D$418,$A15,Data!$H$2:$H$418,"United States") | E15: =COUNTIFS(Data!$D$2:$D$418,$A15,Data!$H$2:$H$418,"LatAm legislature") | F15: =COUNTIFS(Data!$D$2:$D$418,$A15,Data!$H$2:$H$418,"China") | G15: =COUNTIFS(Data!$D$2:$D$418,$A15,Data!$H$2:$H$418,"Other (business, civil society, third countries)") | H15: =COUNTIFS(Data!$D$2:$D$418,$A15,Data!$H$2:$H$418,"LatAm party/candidate") | I15: =COUNTIFS(Data!$D$2:$D$418,$A15,Data!$H$2:$H$418,"LatAm state company") | J15: =COUNTIFS(Data!$D$2:$D$418,$A15,Data!$H$2:$H$418,"LatAm judiciary") | K15: =SUM(C6:J6)
A16: PAN | B16: Panama | C16: =COUNTIFS(Data!$D$2:$D$418,$A16,Data!$H$2:$H$418,"LatAm executive") | D16: =COUNTIFS(Data!$D$2:$D$418,$A16,Data!$H$2:$H$418,"United States") | E16: =COUNTIFS(Data!$D$2:$D$418,$A16,Data!$H$2:$H$418,"LatAm legislature") | F16: =COUNTIFS(Data!$D$2:$D$418,$A16,Data!$H$2:$H$418,"China") | G16: =COUNTIFS(Data!$D$2:$D$418,$A16,Data!$H$2:$H$418,"Other (business, civil society, third countries)") | H16: =COUNTIFS(Data!$D$2:$D$418,$A16,Data!$H$2:$H$418,"LatAm party/candidate") | I16: =COUNTIFS(Data!$D$2:$D$418,$A16,Data!$H$2:$H$418,"LatAm state company") | J16: =COUNTIFS(Data!$D$2:$D$418,$A16,Data!$H$2:$H$418,"LatAm judiciary") | K16: =SUM(C6:J6)
A17: COL | B17: Colombia | C17: =COUNTIFS(Data!$D$2:$D$418,$A17,Data!$H$2:$H$418,"LatAm executive") | D17: =COUNTIFS(Data!$D$2:$D$418,$A17,Data!$H$2:$H$418,"United States") | E17: =COUNTIFS(Data!$D$2:$D$418,$A17,Data!$H$2:$H$418,"LatAm legislature") | F17: =COUNTIFS(Data!$D$2:$D$418,$A17,Data!$H$2:$H$418,"China") | G17: =COUNTIFS(Data!$D$2:$D$418,$A17,Data!$H$2:$H$418,"Other (business, civil society, third countries)") | H17: =COUNTIFS(Data!$D$2:$D$418,$A17,Data!$H$2:$H$418,"LatAm party/candidate") | I17: =COUNTIFS(Data!$D$2:$D$418,$A17,Data!$H$2:$H$418,"LatAm state company") | J17: =COUNTIFS(Data!$D$2:$D$418,$A17,Data!$H$2:$H$418,"LatAm judiciary") | K17: =SUM(C6:J6)
A18: GUY | B18: Guyana | C18: =COUNTIFS(Data!$D$2:$D$418,$A18,Data!$H$2:$H$418,"LatAm executive") | D18: =COUNTIFS(Data!$D$2:$D$418,$A18,Data!$H$2:$H$418,"United States") | E18: =COUNTIFS(Data!$D$2:$D$418,$A18,Data!$H$2:$H$418,"LatAm legislature") | F18: =COUNTIFS(Data!$D$2:$D$418,$A18,Data!$H$2:$H$418,"China") | G18: =COUNTIFS(Data!$D$2:$D$418,$A18,Data!$H$2:$H$418,"Other (business, civil society, third countries)") | H18: =COUNTIFS(Data!$D$2:$D$418,$A18,Data!$H$2:$H$418,"LatAm party/candidate") | I18: =COUNTIFS(Data!$D$2:$D$418,$A18,Data!$H$2:$H$418,"LatAm state company") | J18: =COUNTIFS(Data!$D$2:$D$418,$A18,Data!$H$2:$H$418,"LatAm judiciary") | K18: =SUM(C6:J6)
A19: VEN | B19: Venezuela | C19: =COUNTIFS(Data!$D$2:$D$418,$A19,Data!$H$2:$H$418,"LatAm executive") | D19: =COUNTIFS(Data!$D$2:$D$418,$A19,Data!$H$2:$H$418,"United States") | E19: =COUNTIFS(Data!$D$2:$D$418,$A19,Data!$H$2:$H$418,"LatAm legislature") | F19: =COUNTIFS(Data!$D$2:$D$418,$A19,Data!$H$2:$H$418,"China") | G19: =COUNTIFS(Data!$D$2:$D$418,$A19,Data!$H$2:$H$418,"Other (business, civil society, third countries)") | H19: =COUNTIFS(Data!$D$2:$D$418,$A19,Data!$H$2:$H$418,"LatAm party/candidate") | I19: =COUNTIFS(Data!$D$2:$D$418,$A19,Data!$H$2:$H$418,"LatAm state company") | J19: =COUNTIFS(Data!$D$2:$D$418,$A19,Data!$H$2:$H$418,"LatAm judiciary") | K19: =SUM(C6:J6)
A20: PRY | B20: Paraguay | C20: =COUNTIFS(Data!$D$2:$D$418,$A20,Data!$H$2:$H$418,"LatAm executive") | D20: =COUNTIFS(Data!$D$2:$D$418,$A20,Data!$H$2:$H$418,"United States") | E20: =COUNTIFS(Data!$D$2:$D$418,$A20,Data!$H$2:$H$418,"LatAm legislature") | F20: =COUNTIFS(Data!$D$2:$D$418,$A20,Data!$H$2:$H$418,"China") | G20: =COUNTIFS(Data!$D$2:$D$418,$A20,Data!$H$2:$H$418,"Other (business, civil society, third countries)") | H20: =COUNTIFS(Data!$D$2:$D$418,$A20,Data!$H$2:$H$418,"LatAm party/candidate") | I20: =COUNTIFS(Data!$D$2:$D$418,$A20,Data!$H$2:$H$418,"LatAm state company") | J20: =COUNTIFS(Data!$D$2:$D$418,$A20,Data!$H$2:$H$418,"LatAm judiciary") | K20: =SUM(C6:J6)
A21: SUR | B21: Suriname | C21: =COUNTIFS(Data!$D$2:$D$418,$A21,Data!$H$2:$H$418,"LatAm executive") | D21: =COUNTIFS(Data!$D$2:$D$418,$A21,Data!$H$2:$H$418,"United States") | E21: =COUNTIFS(Data!$D$2:$D$418,$A21,Data!$H$2:$H$418,"LatAm legislature") | F21: =COUNTIFS(Data!$D$2:$D$418,$A21,Data!$H$2:$H$418,"China") | G21: =COUNTIFS(Data!$D$2:$D$418,$A21,Data!$H$2:$H$418,"Other (business, civil society, third countries)") | H21: =COUNTIFS(Data!$D$2:$D$418,$A21,Data!$H$2:$H$418,"LatAm party/candidate") | I21: =COUNTIFS(Data!$D$2:$D$418,$A21,Data!$H$2:$H$418,"LatAm state company") | J21: =COUNTIFS(Data!$D$2:$D$418,$A21,Data!$H$2:$H$418,"LatAm judiciary") | K21: =SUM(C6:J6)
B22: Total | C22: =SUM(C8:C21) | D22: =SUM(D8:D21) | E22: =SUM(E8:E21) | F22: =SUM(F8:F21) | G22: =SUM(G8:G21) | H22: =SUM(H8:H21) | I22: =SUM(I8:I21) | J22: =SUM(J8:J21) | K22: =SUM(K8:K21)
B23: Check: rows in Data | K23: =COUNTA(Data!$A$2:$A$418)
A25: Stance toward China by country
A26: Code | B26: Country | C26: positive | D26: neutral | E26: mixed | F26: negative | G26: not mentioned | H26: Total
A27: CHL | B27: Chile | C27: =COUNTIFS(Data!$D$2:$D$418,$A27,Data!$Q$2:$Q$418,"positive") | D27: =COUNTIFS(Data!$D$2:$D$418,$A27,Data!$Q$2:$Q$418,"neutral") | E27: =COUNTIFS(Data!$D$2:$D$418,$A27,Data!$Q$2:$Q$418,"mixed") | F27: =COUNTIFS(Data!$D$2:$D$418,$A27,Data!$Q$2:$Q$418,"negative") | G27: =COUNTIFS(Data!$D$2:$D$418,$A27,Data!$Q$2:$Q$418,"not_mentioned") | H27: =SUM(C21:G21)
A28: PER | B28: Peru | C28: =COUNTIFS(Data!$D$2:$D$418,$A28,Data!$Q$2:$Q$418,"positive") | D28: =COUNTIFS(Data!$D$2:$D$418,$A28,Data!$Q$2:$Q$418,"neutral") | E28: =COUNTIFS(Data!$D$2:$D$418,$A28,Data!$Q$2:$Q$418,"mixed") | F28: =COUNTIFS(Data!$D$2:$D$418,$A28,Data!$Q$2:$Q$418,"negative") | G28: =COUNTIFS(Data!$D$2:$D$418,$A28,Data!$Q$2:$Q$418,"not_mentioned") | H28: =SUM(C21:G21)
A29: BRA | B29: Brazil | C29: =COUNTIFS(Data!$D$2:$D$418,$A29,Data!$Q$2:$Q$418,"positive") | D29: =COUNTIFS(Data!$D$2:$D$418,$A29,Data!$Q$2:$Q$418,"neutral") | E29: =COUNTIFS(Data!$D$2:$D$418,$A29,Data!$Q$2:$Q$418,"mixed") | F29: =COUNTIFS(Data!$D$2:$D$418,$A29,Data!$Q$2:$Q$418,"negative") | G29: =COUNTIFS(Data!$D$2:$D$418,$A29,Data!$Q$2:$Q$418,"not_mentioned") | H29: =SUM(C21:G21)
A30: ARG | B30: Argentina | C30: =COUNTIFS(Data!$D$2:$D$418,$A30,Data!$Q$2:$Q$418,"positive") | D30: =COUNTIFS(Data!$D$2:$D$418,$A30,Data!$Q$2:$Q$418,"neutral") | E30: =COUNTIFS(Data!$D$2:$D$418,$A30,Data!$Q$2:$Q$418,"mixed") | F30: =COUNTIFS(Data!$D$2:$D$418,$A30,Data!$Q$2:$Q$418,"negative") | G30: =COUNTIFS(Data!$D$2:$D$418,$A30,Data!$Q$2:$Q$418,"not_mentioned") | H30: =SUM(C21:G21)
A31: BOL | B31: Bolivia | C31: =COUNTIFS(Data!$D$2:$D$418,$A31,Data!$Q$2:$Q$418,"positive") | D31: =COUNTIFS(Data!$D$2:$D$418,$A31,Data!$Q$2:$Q$418,"neutral") | E31: =COUNTIFS(Data!$D$2:$D$418,$A31,Data!$Q$2:$Q$418,"mixed") | F31: =COUNTIFS(Data!$D$2:$D$418,$A31,Data!$Q$2:$Q$418,"negative") | G31: =COUNTIFS(Data!$D$2:$D$418,$A31,Data!$Q$2:$Q$418,"not_mentioned") | H31: =SUM(C21:G21)
A32: MEX | B32: Mexico | C32: =COUNTIFS(Data!$D$2:$D$418,$A32,Data!$Q$2:$Q$418,"positive") | D32: =COUNTIFS(Data!$D$2:$D$418,$A32,Data!$Q$2:$Q$418,"neutral") | E32: =COUNTIFS(Data!$D$2:$D$418,$A32,Data!$Q$2:$Q$418,"mixed") | F32: =COUNTIFS(Data!$D$2:$D$418,$A32,Data!$Q$2:$Q$418,"negative") | G32: =COUNTIFS(Data!$D$2:$D$418,$A32,Data!$Q$2:$Q$418,"not_mentioned") | H32: =SUM(C21:G21)
A33: REG | B33: Regional | C33: =COUNTIFS(Data!$D$2:$D$418,$A33,Data!$Q$2:$Q$418,"positive") | D33: =COUNTIFS(Data!$D$2:$D$418,$A33,Data!$Q$2:$Q$418,"neutral") | E33: =COUNTIFS(Data!$D$2:$D$418,$A33,Data!$Q$2:$Q$418,"mixed") | F33: =COUNTIFS(Data!$D$2:$D$418,$A33,Data!$Q$2:$Q$418,"negative") | G33: =COUNTIFS(Data!$D$2:$D$418,$A33,Data!$Q$2:$Q$418,"not_mentioned") | H33: =SUM(C21:G21)
A34: ECU | B34: Ecuador | C34: =COUNTIFS(Data!$D$2:$D$418,$A34,Data!$Q$2:$Q$418,"positive") | D34: =COUNTIFS(Data!$D$2:$D$418,$A34,Data!$Q$2:$Q$418,"neutral") | E34: =COUNTIFS(Data!$D$2:$D$418,$A34,Data!$Q$2:$Q$418,"mixed") | F34: =COUNTIFS(Data!$D$2:$D$418,$A34,Data!$Q$2:$Q$418,"negative") | G34: =COUNTIFS(Data!$D$2:$D$418,$A34,Data!$Q$2:$Q$418,"not_mentioned") | H34: =SUM(C21:G21)
A35: PAN | B35: Panama | C35: =COUNTIFS(Data!$D$2:$D$418,$A35,Data!$Q$2:$Q$418,"positive") | D35: =COUNTIFS(Data!$D$2:$D$418,$A35,Data!$Q$2:$Q$418,"neutral") | E35: =COUNTIFS(Data!$D$2:$D$418,$A35,Data!$Q$2:$Q$418,"mixed") | F35: =COUNTIFS(Data!$D$2:$D$418,$A35,Data!$Q$2:$Q$418,"negative") | G35: =COUNTIFS(Data!$D$2:$D$418,$A35,Data!$Q$2:$Q$418,"not_mentioned") | H35: =SUM(C21:G21)
A36: COL | B36: Colombia | C36: =COUNTIFS(Data!$D$2:$D$418,$A36,Data!$Q$2:$Q$418,"positive") | D36: =COUNTIFS(Data!$D$2:$D$418,$A36,Data!$Q$2:$Q$418,"neutral") | E36: =COUNTIFS(Data!$D$2:$D$418,$A36,Data!$Q$2:$Q$418,"mixed") | F36: =COUNTIFS(Data!$D$2:$D$418,$A36,Data!$Q$2:$Q$418,"negative") | G36: =COUNTIFS(Data!$D$2:$D$418,$A36,Data!$Q$2:$Q$418,"not_mentioned") | H36: =SUM(C21:G21)
A37: GUY | B37: Guyana | C37: =COUNTIFS(Data!$D$2:$D$418,$A37,Data!$Q$2:$Q$418,"positive") | D37: =COUNTIFS(Data!$D$2:$D$418,$A37,Data!$Q$2:$Q$418,"neutral") | E37: =COUNTIFS(Data!$D$2:$D$418,$A37,Data!$Q$2:$Q$418,"mixed") | F37: =COUNTIFS(Data!$D$2:$D$418,$A37,Data!$Q$2:$Q$418,"negative") | G37: =COUNTIFS(Data!$D$2:$D$418,$A37,Data!$Q$2:$Q$418,"not_mentioned") | H37: =SUM(C21:G21)
A38: VEN | B38: Venezuela | C38: =COUNTIFS(Data!$D$2:$D$418,$A38,Data!$Q$2:$Q$418,"positive") | D38: =COUNTIFS(Data!$D$2:$D$418,$A38,Data!$Q$2:$Q$418,"neutral") | E38: =COUNTIFS(Data!$D$2:$D$418,$A38,Data!$Q$2:$Q$418,"mixed") | F38: =COUNTIFS(Data!$D$2:$D$418,$A38,Data!$Q$2:$Q$418,"negative") | G38: =COUNTIFS(Data!$D$2:$D$418,$A38,Data!$Q$2:$Q$418,"not_mentioned") | H38: =SUM(C21:G21)
A39: PRY | B39: Paraguay | C39: =COUNTIFS(Data!$D$2:$D$418,$A39,Data!$Q$2:$Q$418,"positive") | D39: =COUNTIFS(Data!$D$2:$D$418,$A39,Data!$Q$2:$Q$418,"neutral") | E39: =COUNTIFS(Data!$D$2:$D$418,$A39,Data!$Q$2:$Q$418,"mixed") | F39: =COUNTIFS(Data!$D$2:$D$418,$A39,Data!$Q$2:$Q$418,"negative") | G39: =COUNTIFS(Data!$D$2:$D$418,$A39,Data!$Q$2:$Q$418,"not_mentioned") | H39: =SUM(C21:G21)
A40: SUR | B40: Suriname | C40: =COUNTIFS(Data!$D$2:$D$418,$A40,Data!$Q$2:$Q$418,"positive") | D40: =COUNTIFS(Data!$D$2:$D$418,$A40,Data!$Q$2:$Q$418,"neutral") | E40: =COUNTIFS(Data!$D$2:$D$418,$A40,Data!$Q$2:$Q$418,"mixed") | F40: =COUNTIFS(Data!$D$2:$D$418,$A40,Data!$Q$2:$Q$418,"negative") | G40: =COUNTIFS(Data!$D$2:$D$418,$A40,Data!$Q$2:$Q$418,"not_mentioned") | H40: =SUM(C21:G21)
B41: Total | C41: =SUM(C27:C40) | D41: =SUM(D27:D40) | E41: =SUM(E27:E40) | F41: =SUM(F27:F40) | G41: =SUM(G27:G40) | H41: =SUM(H27:H40)
A43: Stance toward the US by country
A44: Code | B44: Country | C44: positive | D44: neutral | E44: mixed | F44: negative | G44: not mentioned | H44: Total
A45: CHL | B45: Chile | C45: =COUNTIFS(Data!$D$2:$D$418,$A45,Data!$R$2:$R$418,"positive") | D45: =COUNTIFS(Data!$D$2:$D$418,$A45,Data!$R$2:$R$418,"neutral") | E45: =COUNTIFS(Data!$D$2:$D$418,$A45,Data!$R$2:$R$418,"mixed") | F45: =COUNTIFS(Data!$D$2:$D$418,$A45,Data!$R$2:$R$418,"negative") | G45: =COUNTIFS(Data!$D$2:$D$418,$A45,Data!$R$2:$R$418,"not_mentioned") | H45: =SUM(C35:G35)
...

Sheet Data
A1: id | B1: date | C1: year | D1: country | E1: speaker_name | F1: speaker_role | G1: speaker_type | H1: speaker_bloc | I1: speaker_country | J1: party_or_affiliation | K1: channel | L1: event_context | M1: minerals | N1: hs6_links | O1: themes | P1: counterparts_mentioned | Q1: stance_china | R1: stance_us | S1: related_entities | T1: summary_en | U1: quote_original | V1: quote_en | W1: language | X1: source_name | Y1: source_url | Z1: source_type | AA1: verification | AB1: notes | AC1: research_batch
A2: PS-0001 | B2: 2019-03 | C2: 2019 | D2: PER | E2: Paola Bustamante | F2: Minister of Development and Social Inclusion of Peru | G2: minister_cabinet | H2: LatAm executive | I2: PER | K2: press_conference | L2: Fuerabamba blockade of Las Bambas mining road; failed ministerial negotiation visit | M2: copper | N2: 260300;740200;740311 | O2: labor_social_conflict;indigenous_community_rights | P2: CHN | Q2: not_mentioned | R2: not_mentioned | S2: Las Bambas; MMG; China Minmetals | T2: After protesters threw rocks at a government helicopter carrying a three-minister delegation to negotiate an end to a 51-day Fuerabamba community blockade of the Las Bambas copper mine road, Bustamante said the government would maintain its willingness to dialogue. | U2: We went with a disposition for dialogue and that's why we're going to continue with that disposition and see how things shape up tomorrow. | V2: We went with a disposition for dialogue and that's why we're going to continue with that disposition and see how things shape up tomorrow. | W2: en | X2: Reuters via The Borneo Post (PressReader) | Y2: https://www.pressreader.com/malaysia/the-borneo-post-sabah/20190329/282248076914526 | Z2: news_media | AA2: secondary_reported | AB2: Exact day not given (Wednesday before 29 Mar 2019, likely 27 Mar); quote is English wire translation of Spanish original | AC2: PER
A3: PS-0002 | B3: 2019-03-05 | C3: 2019 | D3: BRA | E3: Bento Albuquerque | F3: Minister of Mines and Energy of Brazil | G3: minister_cabinet | H3: LatAm executive | I3: BRA | K3: speech | L3: Meeting with mining investors in Canada (PDAC, Toronto) | M3: mining_general | O3: indigenous_community_rights;foreign_investment;sovereignty | P3: CAN | Q3: not_mentioned | R3: not_mentioned | S3: INB | T3: Albuquerque told investors in Canada that the government was studying authorising mining in indigenous lands and border areas, arguing restrictions fostered illegal activity, and favoured opening uranium research to private investment. | U3: As restrições aplicadas a essas áreas não têm favorecido seu desenvolvimento. | V3: The restrictions applied to these areas have not favoured their development. | W3: pt | X3: Congresso em Foco | Y3: https://congressoemfoco.com.br/economia/governo-planeja-liberar-mineracao-em-terras-indigenas-diz-ministro | Z3: news_media | AA3: secondary_reported | AB3: Event name PDAC inferred from date/location | AC3: BRA
A4: PS-0003 | B4: 2019-07-16 | C4: 2019 | D4: PER | E4: Elmer Cáceres Llica | F4: Regional Governor of Arequipa | G4: subnational_gov | H4: LatAm executive | I4: PER | K4: press_conference | L4: Tía María license protests, Tambo Valley | M4: copper | N4: 260300;740200;740311 | O4: environment_water;labor_social_conflict | P4: none | Q4: not_mentioned | R4: not_mentioned | S4: Tía María; Southern Copper | T4: The Arequipa governor, backed by over 50 civil organizations, gave the central government 72 hours to declare the Tía María construction license null, while pursuing legal remedies and peaceful protests. | U4: Le daremos al Gobierno central 72 horas para que resuelva el tema de la licencia de construcción, o sea que declare su nulidad de oficio | V4: We will give the central government 72 hours to resolve the construction license issue, that is, to declare it null ex officio | W4: es | X4: La República | Y4: https://larepublica.pe/sociedad/2019/07/16/gobernador-de-arequipa-da-72-horas-a-vizcarra-para-cancelar-licencia-de-tia-maria | Z4: news_media | AA4: secondary_reported | AC4: PER
A5: PS-0004 | B5: 2019-07-16 | C5: 2019 | D5: PER | E5: Martín Vizcarra | F5: President of Peru | G5: head_of_state | H5: LatAm executive | I5: PER | K5: press_conference | L5: Protests over Tía María construction license granted to Southern Peru (9 Jul 2019) | M5: copper | N5: 260300;740200;740311 | O5: labor_social_conflict;environment_water;foreign_investment | P5: none | Q5: not_mentioned | R5: not_mentioned | S5: Tía María; Southern Peru Copper; Grupo México | T5: Vizcarra said the construction license granted to Southern Peru for Tía María could not be annulled because the company had completed the administrative process, but called for dialogue and said construction would need proper conditions. | U5: No se puede anular, tenemos que conversar y fruto del diálogo, encontremos las soluciones y consensos | V5: It cannot be annulled; we have to talk, and through dialogue find solutions and consensus | W5: es | X5: El Búho | Y5: https://elbuho.pe/archivo/2019/07/16/martin-vizcarra-sobre-tia-maria-no-se-puede-anular-licencia-tenemos-que-conversar/index.html | Z5: news_media | AA5: secondary_reported | AC5: PER
A6: PS-0005 | B6: 2019-09-06 | C6: 2019 | D6: CHL | E6: Pablo Terrazas | F6: Executive Vice President of CORFO | G6: other_executive | H6: LatAm executive | I6: CHL | K6: legislative_debate | L6: Chamber of Deputies Economy Commission session on lithium and Tianqi-SQM | M6: lithium | N6: 253090;282520;283691 | O6: technology_transfer;value_added_industrialization;foreign_investment | P6: CHN | Q6: neutral | R6: not_mentioned | S6: CORFO; SQM; Tianqi; Instituto Chileno de Tecnologías Limpias | T6: CORFO head briefed deputies on lithium contracts, Tianqi's stake in SQM and the planned Chilean Institute of Clean Technologies in Antofagasta, funded with SQM contributions, for lithium R&D. | U6: De aquí a fin de año, ya vamos a tener a algún consorcio liderando la creación de este instituto | V6: By the end of the year we will have a consortium leading the creation of this institute | W6: es | X6: Cámara de Diputadas y Diputados | Y6: https://www.camara.cl/cms/2019/09/06/vicepresidente-de-corfo-informo-sobre-situacion-y-negociacion-del-litio/ | Z6: legislative_record | AA6: primary_verified | AB6: Quote truncated to stay within 30 words; institute to have >US$200m for R&D | AC6: CHL
A7: PS-0006 | B7: 2019-09-06 | C7: 2019 | D7: CHL | E7: Renato Garín | F7: Deputy, Chair-level member of Economy Commission | G7: legislator | H7: LatAm legislature | I7: CHL | J7: Independent | K7: legislative_debate | L7: Chamber of Deputies Economy Commission session on lithium and Tianqi-SQM | M7: lithium | N7: 253090;282520;283691 | O7: sovereignty;geopolitics_security;technology_transfer | P7: CHN | Q7: negative | R7: not_mentioned | S7: SQM; Tianqi | T7: Deputy Garín voiced concern about Chinese state influence over SQM through Tianqi and said Chile must retain sovereignty over its lithium resources and technology development. | W7: es | X7: Cámara de Diputadas y Diputados | Y7: https://www.camara.cl/cms/2019/09/06/vicepresidente-de-corfo-informo-sobre-situacion-y-negociacion-del-litio/ | Z7: legislative_record | AA7: primary_verified | AB7: Paraphrase from Chamber press note; no verbatim quote | AC7: CHL
